Workbook

Sheet Legenda
A1: SERVIZI ECOLOGICI S.R.L. – Gestione contatti, servizi e obblighi di legge
A2: Creato il 25/09/2026 – fonti: area clienti Italiaonline/PgCasa, sito serviziecologici.it, normativa vigente
A4: Foglio | B4: A cosa serve | C4: Cosa compilare
A5: Servizi e obblighi | B5: Tutti i servizi dell'azienda con autorizzazioni, documenti, sicurezza, trasporto e scadenze di legge | C5: Colonna 'Verifica interna' (es. n. iscrizione Albo, scadenza)
A6: Iscrizione Albo | B6: Categorie, classi e scadenze dell'iscrizione MI03807 con stato automatico (VALIDA / RINNOVARE ORA) | C6: Aggiornare dopo ogni rinnovo
A7: Obblighi trasversali | B7: Obblighi che valgono per tutta l'azienda (Albo, RENTRI, MUD, DVR, privacy contatti…) | C7: Colonne 'Scadenza' e 'Responsabile'
A8: Registro | B8: Un rigo per ogni contatto (PgCasa, telefonate, moduli sito, Google…): esito PRESO / NON PRESO e motivo | C8: Tutte le celle gialle. Menù a tendina su Fonte, Tipo cliente, Area, Esito, Motivo
A9: Statistiche | B9: Conteggi automatici per servizio, zona, fonte, tipo cliente, esito e motivo; % lavori presi; costo per lavoro preso | C9: Niente: si aggiorna da solo
A10: Motivi | B10: Elenco dei motivi di lavoro non preso (usato dal menù a tendina) | C10: Aggiungere motivi in fondo se servono
A11: Pacchetti | B11: Pacchetti di servizi per tipo di cliente, con l'obbligo di legge che il pacchetto risolve | C11: Prezzo indicativo e note commerciali
A13: Colori | B13: Celle gialle = da compilare. Celle verdi = intestazioni di area. Il resto sono formule o testi di riferimento.
A14: Attenzione | B14: Le indicazioni normative sono una sintesi operativa, non un parere legale: verificare sempre con il consulente ambientale/RSPP e sul testo vigente delle norme.
A15: Registro chiamate | B15: Importate le 168 chiamate del file reg.chiamate.pdf (Reception, 2026) + 16 richieste PgCasa. Il registro originale NON ha l'esito: la colonna Esito è impostata a DA VERIFICARE, va aggiornata con PRESO / NON PRESO + Motivo.
A16: Ipotesi di lettura | B16: IT CANNE = ispezione TV canne fumarie; IT FOGNA = ispezione TV fognatura; PULIZ./PULIZIA, ANALISI e INSTALLAZI sono in area DA SPECIFICARE perché dal registro non si capisce quale servizio. Correggere dove serve.
A17: Dati Italiaonline (ultimi 6 mesi) | B17: 14.533 impression · 7.495 visualizzazioni · 2.859 visite · 500 chiamate · 331 indicazioni stradali · 157 clic sito · 37 moduli contatto · 17 preventivi · saldo PgCasa 62 €

Sheet Statistiche
A1: Statistiche contatti
A2: Si aggiornano da sole dal foglio Registro
A4: Totale contatti | B4: =COUNTA(Registro!$D$5:$D$804) -> 184
A5: Lavori PRESI | B5: =COUNTIF(Registro!$M$5:$M$804,"PRESO") -> 0
A6: NON PRESI | B6: =COUNTIF(Registro!$M$5:$M$804,"NON PRESO") -> 0
A7: Esito ancora da inserire | B7: =B4-B5-B6 -> 184
A8: % presi sui contatti chiusi | B8: =IFERROR(B5/(B5+B6),0) -> 0
A9: Contatti da Italiaonline (chiamate + PgCasa) | B9: =COUNTIF(Registro!$B$5:$B$804,"Italiaonline")+COUNTIF(Registro!$B$5:$B$804,"PgCasa (Italiaonline)") -> 56
A10: % contatti da Italiaonline | B10: =IFERROR(B9/B4,0) -> 0.30434783
A11: Costo contatti PgCasa € | B11: =SUM(Registro!$Q$5:$Q$804) -> 123
A12: Costo per lavoro preso € | B12: =IFERROR(B11/B5,0) -> 0
A13: Valore lavori fatti € | B13: =SUM(Registro!$P$5:$P$804) -> 0
A16: Per fonte del contatto (da dove ci conoscono)
A17: Fonte | B17: Contatti | C17: Presi | D17: Non presi | E17: Esito da inserire / in attesa | F17: % presi (sui chiusi) | G17: Costo contatti € | H17: Valore lavori €
A18: PgCasa (Italiaonline) | B18: =COUNTIF(Registro!$B$5:$B$804,$A18) -> 16 | C18: =COUNTIFS(Registro!$B$5:$B$804,$A18,Registro!$M$5:$M$804,"PRESO") -> 0 | D18: =COUNTIFS(Registro!$B$5:$B$804,$A18,Registro!$M$5:$M$804,"NON PRESO") -> 0 | E18: =B18-C18-D18 -> 16 | F18: =IFERROR(C18/(C18+D18),0) -> 0 | G18: =SUMIF(Registro!$B$5:$B$804,$A18,Registro!$Q$5:$Q$804) -> 123 | H18: =SUMIFS(Registro!$P$5:$P$804,Registro!$B$5:$B$804,$A18,Registro!$M$5:$M$804,"PRESO") -> 0
A19: Italiaonline | B19: =COUNTIF(Registro!$B$5:$B$804,$A19) -> 40 | C19: =COUNTIFS(Registro!$B$5:$B$804,$A19,Registro!$M$5:$M$804,"PRESO") -> 0 | D19: =COUNTIFS(Registro!$B$5:$B$804,$A19,Registro!$M$5:$M$804,"NON PRESO") -> 0 | E19: =B19-C19-D19 -> 40 | F19: =IFERROR(C19/(C19+D19),0) -> 0 | G19: =SUMIF(Registro!$B$5:$B$804,$A19,Registro!$Q$5:$Q$804) -> 0 | H19: =SUMIFS(Registro!$P$5:$P$804,Registro!$B$5:$B$804,$A19,Registro!$M$5:$M$804,"PRESO") -> 0
A20: Internet | B20: =COUNTIF(Registro!$B$5:$B$804,$A20) -> 37 | C20: =COUNTIFS(Registro!$B$5:$B$804,$A20,Registro!$M$5:$M$804,"PRESO") -> 0 | D20: =COUNTIFS(Registro!$B$5:$B$804,$A20,Registro!$M$5:$M$804,"NON PRESO") -> 0 | E20: =B20-C20-D20 -> 37 | F20: =IFERROR(C20/(C20+D20),0) -> 0 | G20: =SUMIF(Registro!$B$5:$B$804,$A20,Registro!$Q$5:$Q$804) -> 0 | H20: =SUMIFS(Registro!$P$5:$P$804,Registro!$B$5:$B$804,$A20,Registro!$M$5:$M$804,"PRESO") -> 0
A21: Passaparola | B21: =COUNTIF(Registro!$B$5:$B$804,$A21) -> 83 | C21: =COUNTIFS(Registro!$B$5:$B$804,$A21,Registro!$M$5:$M$804,"PRESO") -> 0 | D21: =COUNTIFS(Registro!$B$5:$B$804,$A21,Registro!$M$5:$M$804,"NON PRESO") -> 0 | E21: =B21-C21-D21 -> 83 | F21: =IFERROR(C21/(C21+D21),0) -> 0 | G21: =SUMIF(Registro!$B$5:$B$804,$A21,Registro!$Q$5:$Q$804) -> 0 | H21: =SUMIFS(Registro!$P$5:$P$804,Registro!$B$5:$B$804,$A21,Registro!$M$5:$M$804,"PRESO") -> 0
A22: Pagine Gialle | B22: =COUNTIF(Registro!$B$5:$B$804,$A22) -> 1 | C22: =COUNTIFS(Registro!$B$5:$B$804,$A22,Registro!$M$5:$M$804,"PRESO") -> 0 | D22: =COUNTIFS(Registro!$B$5:$B$804,$A22,Registro!$M$5:$M$804,"NON PRESO") -> 0 | E22: =B22-C22-D22 -> 1 | F22: =IFERROR(C22/(C22+D22),0) -> 0 | G22: =SUMIF(Registro!$B$5:$B$804,$A22,Registro!$Q$5:$Q$804) -> 0 | H22: =SUMIFS(Registro!$P$5:$P$804,Registro!$B$5:$B$804,$A22,Registro!$M$5:$M$804,"PRESO") -> 0
A23: Quotidiani Online | B23: =COUNTIF(Registro!$B$5:$B$804,$A23) -> 2 | C23: =COUNTIFS(Registro!$B$5:$B$804,$A23,Registro!$M$5:$M$804,"PRESO") -> 0 | D23: =COUNTIFS(Registro!$B$5:$B$804,$A23,Registro!$M$5:$M$804,"NON PRESO") -> 0 | E23: =B23-C23-D23 -> 2 | F23: =IFERROR(C23/(C23+D23),0) -> 0 | G23: =SUMIF(Registro!$B$5:$B$804,$A23,Registro!$Q$5:$Q$804) -> 0 | H23: =SUMIFS(Registro!$P$5:$P$804,Registro!$B$5:$B$804,$A23,Registro!$M$5:$M$804,"PRESO") -> 0
A24: Pubblicità Automezzi | B24: =COUNTIF(Registro!$B$5:$B$804,$A24) -> 1 | C24: =COUNTIFS(Registro!$B$5:$B$804,$A24,Registro!$M$5:$M$804,"PRESO") -> 0 | D24: =COUNTIFS(Registro!$B$5:$B$804,$A24,Registro!$M$5:$M$804,"NON PRESO") -> 0 | E24: =B24-C24-D24 -> 1 | F24: =IFERROR(C24/(C24+D24),0) -> 0 | G24: =SUMIF(Registro!$B$5:$B$804,$A24,Registro!$Q$5:$Q$804) -> 0 | H24: =SUMIFS(Registro!$P$5:$P$804,Registro!$B$5:$B$804,$A24,Registro!$M$5:$M$804,"PRESO") -> 0
A25: Manifesti deratt. | B25: =COUNTIF(Registro!$B$5:$B$804,$A25) -> 1 | C25: =COUNTIFS(Registro!$B$5:$B$804,$A25,Registro!$M$5:$M$804,"PRESO") -> 0 | D25: =COUNTIFS(Registro!$B$5:$B$804,$A25,Registro!$M$5:$M$804,"NON PRESO") -> 0 | E25: =B25-C25-D25 -> 1 | F25: =IFERROR(C25/(C25+D25),0) -> 0 | G25: =SUMIF(Registro!$B$5:$B$804,$A25,Registro!$Q$5:$Q$804) -> 0 | H25: =SUMIFS(Registro!$P$5:$P$804,Registro!$B$5:$B$804,$A25,Registro!$M$5:$M$804,"PRESO") -> 0
A26: Imprese Ambiente | B26: =COUNTIF(Registro!$B$5:$B$804,$A26) -> 1 | C26: =COUNTIFS(Registro!$B$5:$B$804,$A26,Registro!$M$5:$M$804,"PRESO") -> 0 | D26: =COUNTIFS(Registro!$B$5:$B$804,$A26,Registro!$M$5:$M$804,"NON PRESO") -> 0 | E26: =B26-C26-D26 -> 1 | F26: =IFERROR(C26/(C26+D26),0) -> 0 | G26: =SUMIF(Registro!$B$5:$B$804,$A26,Registro!$Q$5:$Q$804) -> 0 | H26: =SUMIFS(Registro!$P$5:$P$804,Registro!$B$5:$B$804,$A26,Registro!$M$5:$M$804,"PRESO") -> 0
A27: Bus | B27: =COUNTIF(Registro!$B$5:$B$804,$A27) -> 1 | C27: =COUNTIFS(Registro!$B$5:$B$804,$A27,Registro!$M$5:$M$804,"PRESO") -> 0 | D27: =COUNTIFS(Registro!$B$5:$B$804,$A27,Registro!$M$5:$M$804,"NON PRESO") -> 0 | E27: =B27-C27-D27 -> 1 | F27: =IFERROR(C27/(C27+D27),0) -> 0 | G27: =SUMIF(Registro!$B$5:$B$804,$A27,Registro!$Q$5:$Q$804) -> 0 | H27: =SUMIFS(Registro!$P$5:$P$804,Registro!$B$5:$B$804,$A27,Registro!$M$5:$M$804,"PRESO") -> 0
A28: Altro | B28: =COUNTIF(Registro!$B$5:$B$804,$A28) -> 1 | C28: =COUNTIFS(Registro!$B$5:$B$804,$A28,Registro!$M$5:$M$804,"PRESO") -> 0 | D28: =COUNTIFS(Registro!$B$5:$B$804,$A28,Registro!$M$5:$M$804,"NON PRESO") -> 0 | E28: =B28-C28-D28 -> 1 | F28: =IFERROR(C28/(C28+D28),0) -> 0 | G28: =SUMIF(Registro!$B$5:$B$804,$A28,Registro!$Q$5:$Q$804) -> 0 | H28: =SUMIFS(Registro!$P$5:$P$804,Registro!$B$5:$B$804,$A28,Registro!$M$5:$M$804,"PRESO") -> 0
A29: TOTALE | B29: =SUM(B18:B28) -> 184 | C29: =SUM(C18:C28) -> 0 | D29: =SUM(D18:D28) -> 0 | E29: =SUM(E18:E28) -> 184 | F29: =IFERROR(C29/(C29+D29),0) -> 0 | G29: =SUM(G18:G28) -> 123 | H29: =SUM(H18:H28) -> 0
A31: Per area di servizio
A32: Area | B32: Contatti | C32: Presi | D32: Non presi | E32: Esito da inserire / in attesa | F32: % presi (sui chiusi) | G32: Costo contatti € | H32: Valore lavori €
A33: SPURGHI E RETI | B33: =COUNTIF(Registro!$J$5:$J$804,$A33) -> 30 | C33: =COUNTIFS(Registro!$J$5:$J$804,$A33,Registro!$M$5:$M$804,"PRESO") -> 0 | D33: =COUNTIFS(Registro!$J$5:$J$804,$A33,Registro!$M$5:$M$804,"NON PRESO") -> 0 | E33: =B33-C33-D33 -> 30 | F33: =IFERROR(C33/(C33+D33),0) -> 0 | G33: =SUMIF(Registro!$J$5:$J$804,$A33,Registro!$Q$5:$Q$804) -> 60 | H33: =SUMIFS(Registro!$P$5:$P$804,Registro!$J$5:$J$804,$A33,Registro!$M$5:$M$804,"PRESO") -> 0
A34: RIFIUTI | B34: =COUNTIF(Registro!$J$5:$J$804,$A34) -> 38 | C34: =COUNTIFS(Registro!$J$5:$J$804,$A34,Registro!$M$5:$M$804,"PRESO") -> 0 | D34: =COUNTIFS(Registro!$J$5:$J$804,$A34,Registro!$M$5:$M$804,"NON PRESO") -> 0 | E34: =B34-C34-D34 -> 38 | F34: =IFERROR(C34/(C34+D34),0) -> 0 | G34: =SUMIF(Registro!$J$5:$J$804,$A34,Registro!$Q$5:$Q$804) -> 0 | H34: =SUMIFS(Registro!$P$5:$P$804,Registro!$J$5:$J$804,$A34,Registro!$M$5:$M$804,"PRESO") -> 0
A35: BONIFICHE | B35: =COUNTIF(Registro!$J$5:$J$804,$A35) -> 38 | C35: =COUNTIFS(Registro!$J$5:$J$804,$A35,Registro!$M$5:$M$804,"PRESO") -> 0 | D35: =COUNTIFS(Registro!$J$5:$J$804,$A35,Registro!$M$5:$M$804,"NON PRESO") -> 0 | E35: =B35-C35-D35 -> 38 | F35: =IFERROR(C35/(C35+D35),0) -> 0 | G35: =SUMIF(Registro!$J$5:$J$804,$A35,Registro!$Q$5:$Q$804) -> 0 | H35: =SUMIFS(Registro!$P$5:$P$804,Registro!$J$5:$J$804,$A35,Registro!$M$5:$M$804,"PRESO") -> 0
A36: DISINFESTAZIONE | B36: =COUNTIF(Registro!$J$5:$J$804,$A36) -> 33 | C36: =COUNTIFS(Registro!$J$5:$J$804,$A36,Registro!$M$5:$M$804,"PRESO") -> 0 | D36: =COUNTIFS(Registro!$J$5:$J$804,$A36,Registro!$M$5:$M$804,"NON PRESO") -> 0 | E36: =B36-C36-D36 -> 33 | F36: =IFERROR(C36/(C36+D36),0) -> 0 | G36: =SUMIF(Registro!$J$5:$J$804,$A36,Registro!$Q$5:$Q$804) -> 63 | H36: =SUMIFS(Registro!$P$5:$P$804,Registro!$J$5:$J$804,$A36,Registro!$M$5:$M$804,"PRESO") -> 0
A37: IGIENE IMPIANTI | B37: =COUNTIF(Registro!$J$5:$J$804,$A37) -> 14 | C37: =COUNTIFS(Registro!$J$5:$J$804,$A37,Registro!$M$5:$M$804,"PRESO") -> 0 | D37: =COUNTIFS(Registro!$J$5:$J$804,$A37,Registro!$M$5:$M$804,"NON PRESO") -> 0 | E37: =B37-C37-D37 -> 14 | F37: =IFERROR(C37/(C37+D37),0) -> 0 | G37: =SUMIF(Registro!$J$5:$J$804,$A37,Registro!$Q$5:$Q$804) -> 0 | H37: =SUMIFS(Registro!$P$5:$P$804,Registro!$J$5:$J$804,$A37,Registro!$M$5:$M$804,"PRESO") -> 0
A38: NAUTICA | B38: =COUNTIF(Registro!$J$5:$J$804,$A38) -> 0 | C38: =COUNTIFS(Registro!$J$5:$J$804,$A38,Registro!$M$5:$M$804,"PRESO") -> 0 | D38: =COUNTIFS(Registro!$J$5:$J$804,$A38,Registro!$M$5:$M$804,"NON PRESO") -> 0 | E38: =B38-C38-D38 -> 0 | F38: =IFERROR(C38/(C38+D38),0) -> 0 | G38: =SUMIF(Registro!$J$5:$J$804,$A38,Registro!$Q$5:$Q$804) -> 0 | H38: =SUMIFS(Registro!$P$5:$P$804,Registro!$J$5:$J$804,$A38,Registro!$M$5:$M$804,"PRESO") -> 0
A39: CONSULENZA | B39: =COUNTIF(Registro!$J$5:$J$804,$A39) -> 0 | C39: =COUNTIFS(Registro!$J$5:$J$804,$A39,Registro!$M$5:$M$804,"PRESO") -> 0 | D39: =COUNTIFS(Registro!$J$5:$J$804,$A39,Registro!$M$5:$M$804,"NON PRESO") -> 0 | E39: =B39-C39-D39 -> 0 | F39: =IFERROR(C39/(C39+D39),0) -> 0 | G39: =SUMIF(Registro!$J$5:$J$804,$A39,Registro!$Q$5:$Q$804) -> 0 | H39: =SUMIFS(Registro!$P$5:$P$804,Registro!$J$5:$J$804,$A39,Registro!$M$5:$M$804,"PRESO") -> 0
A40: DA SPECIFICARE | B40: =COUNTIF(Registro!$J$5:$J$804,$A40) -> 31 | C40: =COUNTIFS(Registro!$J$5:$J$804,$A40,Registro!$M$5:$M$804,"PRESO") -> 0 | D40: =COUNTIFS(Registro!$J$5:$J$804,$A40,Registro!$M$5:$M$804,"NON PRESO") -> 0 | E40: =B40-C40-D40 -> 31 | F40: =IFERROR(C40/(C40+D40),0) -> 0 | G40: =SUMIF(Registro!$J$5:$J$804,$A40,Registro!$Q$5:$Q$804) -> 0 | H40: =SUMIFS(Registro!$P$5:$P$804,Registro!$J$5:$J$804,$A40,Registro!$M$5:$M$804,"PRESO") -> 0
A41: TOTALE | B41: =SUM(B33:B40) -> 184 | C41: =SUM(C33:C40) -> 0 | D41: =SUM(D33:D40) -> 0 | E41: =SUM(E33:E40) -> 184 | F41: =IFERROR(C41/(C41+D41),0) -> 0 | G41: =SUM(G33:G40) -> 123 | H41: =SUM(H33:H40) -> 0
A43: Per servizio
A44: Servizio | B44: Contatti | C44: Presi | D44: Non presi | E44: Esito da inserire / in attesa | F44: % presi (sui chiusi) | G44: Costo contatti € | H44: Valore lavori €
A45: Canaljet – autospurgo fosse biologiche, fognature, pozzetti, degrassatori | B45: =COUNTIF(Registro!$K$5:$K$804,$A45) -> 19 | C45: =COUNTIFS(Registro!$K$5:$K$804,$A45,Registro!$M$5:$M$804,"PRESO") -> 0 | D45: =COUNTIFS(Registro!$K$5:$K$804,$A45,Registro!$M$5:$M$804,"NON PRESO") -> 0 | E45: =B45-C45-D45 -> 19 | F45: =IFERROR(C45/(C45+D45),0) -> 0 | G45: =SUMIF(Registro!$K$5:$K$804,$A45,Registro!$Q$5:$Q$804) -> 60 | H45: =SUMIFS(Registro!$P$5:$P$804,Registro!$K$5:$K$804,$A45,Registro!$M$5:$M$804,"PRESO") -> 0
...

Sheet Canali pubblicitari
A1: Canali pubblicitari 2026: costi e contatti ricevuti
A2: Costi da contratti (Italiaonline 11/12/2025, CIBRA 26/02/2025) ed elenco striscioni Contini 2026; contatti dal Registro (gen–22 set 2026)
A4: Canale | B4: Fornitore / contratto | C4: Cosa comprende | D4: Zona | E4: Costo annuo € (IVA escl.) | F4: Contatti 2026 nel registro | G4: Costo per contatto € | H4: Note
A5: Italiaonline – pacchetto digitale | B5: Italiaonline, ordine B2996193-0 del 11/12/2025 (365 gg, 7 rate SDD dal 27/02/2026) | C5: InRete Standard+ 1.099; Sito AI Extra 999; Business Contact scheda 50 + sito 449; Google Ads set-up 649 + budget 4.400; PgCasa ScegliTu 50 + ricarica 150; sconto 1° anno −753,56 | D5: Imperia, Savona, Genova (Google Ads) | E5: 7092.44 | F5: =COUNTIFS(Registro!$B$5:$B$804,"Italiaonline",Registro!$A$5:$A$804,">="&DATE(2026,1,1))+COUNTIFS(Registro!$B$5:$B$804,"PgCasa (Italiaonline)",Registro!$A$5:$A$804,">="&DATE(2026,1,1)) -> 51 | G5: =IF(OR(E5="",E5=0),"",IFERROR(E5/F5,"nessun contatto")) -> 139.06745
A6: Internet – sito / Google | B6: Sito AI Extra e Google Ads compresi nel contratto Italiaonline | C6: Richieste arrivate da 'Internet' (nostro sito, Google, Pagine Gialle) | D6: Tutte | E6: 0 | F6: =COUNTIFS(Registro!$B$5:$B$804,"Internet",Registro!$A$5:$A$804,">="&DATE(2026,1,1))+COUNTIFS(Registro!$B$5:$B$804,"Pagine Gialle",Registro!$A$5:$A$804,">="&DATE(2026,1,1)) -> 38 | G6: =IF(OR(E6="",E6=0),"",IFERROR(E6/F6,"nessun contatto"))
A7: TOTALE DIGITALE (Italiaonline + Internet) | E7: =E5+E6 -> 7092.44 | F7: =F5+F6 -> 89 | G7: =IF(OR(E7="",E7=0),"",IFERROR(E7/F7,"nessun contatto")) -> 79.690337
A8: Cartelloni CIBRA Genova | B8: CIBRA Pubblicità, contratto 26/02/2025, 5 anni | C8: 2 impianti monofacciali: C.C. Coop Sestri Ponente (imp. 404) e Coop Pegli (imp. 483); sostituisce il cartello di Albenga (contratto 103509) | D8: Genova | E8: 2185 | F8: =COUNTIFS(Registro!$T$5:$T$804,"Genova",Registro!$A$5:$A$804,">="&DATE(2026,1,1)) -> 7 | G8: =IF(OR(E8="",E8=0),"",IFERROR(E8/F8,"nessun contatto")) -> 312.14286
A9: Cartellone CIBRA Imperia (Coop) | B9: CIBRA – da elenco striscioni (approvato 2025) | C9: Cartellone presso Coop Imperia | D9: Imperia | F9: =COUNTIFS(Registro!$T$5:$T$804,"Imperia",Registro!$A$5:$A$804,">="&DATE(2026,1,1)) -> 8 | G9: =IF(OR(E9="",E9=0),"",IFERROR(E9/F9,"nessun contatto"))
A10: Striscioni campi sportivi | B10: Vari (vedi foglio Striscioni vs chiamate) | C10: Striscioni 2x1, 2x3, 5x3 presso campi e palestre | D10: Sanremo, Taggia, S.Lorenzo, Imperia, Loano, Borghetto, Albenga | E10: ='Striscioni vs chiamate'!D22 -> 7300 | F10: =COUNTIFS(Registro!$T$5:$T$804,"<>Zone senza striscioni/cartelloni",Registro!$T$5:$T$804,"<>Genova",Registro!$A$5:$A$804,">="&DATE(2026,1,1)) -> 42 | G10: =IF(OR(E10="",E10=0),"",IFERROR(E10/F10,"nessun contatto")) -> 173.80952
A11: Pubblicità automezzi | B11: Interna | C11: Scritte sui camion | D11: Tutte | E11: 0 | F11: =COUNTIFS(Registro!$B$5:$B$804,"Pubblicità Automezzi",Registro!$A$5:$A$804,">="&DATE(2026,1,1)) -> 1 | G11: =IF(OR(E11="",E11=0),"",IFERROR(E11/F11,"nessun contatto"))
A12: Bus | B12: — | C12: Pubblicità su autobus | D12: — | F12: =COUNTIFS(Registro!$B$5:$B$804,"Bus",Registro!$A$5:$A$804,">="&DATE(2026,1,1)) -> 1 | G12: =IF(OR(E12="",E12=0),"",IFERROR(E12/F12,"nessun contatto"))
A13: Manifesti derattizzazione | B13: Interna | C13: Manifesti/cartelli derattizzazione | D13: — | F13: =COUNTIFS(Registro!$B$5:$B$804,"Manifesti deratt.",Registro!$A$5:$A$804,">="&DATE(2026,1,1)) -> 1 | G13: =IF(OR(E13="",E13=0),"",IFERROR(E13/F13,"nessun contatto"))
A14: Quotidiani online | B14: — | C14: Banner su quotidiani online | D14: — | F14: =COUNTIFS(Registro!$B$5:$B$804,"Quotidiani Online",Registro!$A$5:$A$804,">="&DATE(2026,1,1)) -> 2 | G14: =IF(OR(E14="",E14=0),"",IFERROR(E14/F14,"nessun contatto"))
A15: Imprese Ambiente | B15: — | C15: Portale/elenco | D15: — | F15: =COUNTIFS(Registro!$B$5:$B$804,"Imprese Ambiente",Registro!$A$5:$A$804,">="&DATE(2026,1,1)) -> 1 | G15: =IF(OR(E15="",E15=0),"",IFERROR(E15/F15,"nessun contatto"))
A16: Passaparola | B16: — | C16: Clienti, comuni, ecocentri, impianti che ci consigliano | D16: Tutte | E16: 0 | F16: =COUNTIFS(Registro!$B$5:$B$804,"Passaparola",Registro!$A$5:$A$804,">="&DATE(2026,1,1)) -> 83 | G16: =IF(OR(E16="",E16=0),"",IFERROR(E16/F16,"nessun contatto"))
A18: Spesa pubblicitaria da bilancio (conto 68/05/290 PUBBLICITA')
A19: Anno | B19: Pubblicità € | C19: Ricavi totali € | D19: Pubblicità % ricavi
A20: 2023 | B20: 13669.79 | C20: 3041059.5 | D20: =B20/C20 -> 0.0044950749
A21: 2024 | B21: 29322.1 | C21: 2737076.7 | D21: =B21/C21 -> 0.010712926
A22: 2025 | B22: 22795.01 | C22: 2351765 | D22: =B22/C22 -> 0.0096927246
A23: 2026 impegnato (Italiaonline + CIBRA) | B23: =7999.94+E8 -> 10184.94 | E23: Fonte: Bilancio comparato 2023-24-25 (conto economico). 2026: somma contratti noti, striscioni esclusi.

Sheet Striscioni vs chiamate
A1: Striscioni e cartelloni: confronto con il registro chiamate
A2: Fonte: 'Elenco striscioni e pubblicità aggiornato 2026 Contini'. Le chiamate sono quelle del Registro (gen–set 2026) dai comuni della zona
A4: Dove | B4: Zona | C4: Tipo | D4: Costo € (da elenco) | E4: Periodo | F4: Stato / pagamento | G4: Responsabile | H4: Zona registro | I4: Chiamate 2026 dalla zona | J4: di cui dichiarate 'striscione'
A5: RVS Polisportiva | B5: Valle Armea Sanremo palestra | C5: Striscione 2x1 (fisso) | D5: 250 | E5: 2023/2024 | F5: Da rimettere e ripagare 2026 | G5: Massimo | H5: Sanremo / Taggia / S.Lorenzo | I5: =COUNTIFS(Registro!$T$5:$T$804,H5,Registro!$A$5:$A$804,">="&DATE(2026,1,1)) -> 14 | J5: 0
A6: NLP Polisportiva | B6: Valle Armea Sanremo campo B | C6: Striscione vecchio forato | D6: 0 | E6: 2023/2024 | F6: RIMOSSO (strappato) – gratis | G6: Massimo | H6: Sanremo / Taggia / S.Lorenzo | I6: =COUNTIFS(Registro!$T$5:$T$804,H6,Registro!$A$5:$A$804,">="&DATE(2026,1,1)) -> 14 | J6: 0
A7: Tennis Club Arma di Taggia | B7: Arma di Taggia campo sportivo | C7: Striscione 2x3 plastificato | D7: 300 | E7: 2024/2025 | F7: Consegnato; da pagare 2027 | G7: Massimo | H7: Sanremo / Taggia / S.Lorenzo | I7: =COUNTIFS(Registro!$T$5:$T$804,H7,Registro!$A$5:$A$804,">="&DATE(2026,1,1)) -> 14 | J7: 0
A8: BC Station | B8: San Lorenzo al Mare / campo Riva | C8: Striscione 5x3 forato | D8: 700 | E8: 2024/2026 | F8: Concluso – scontato su fattura | G8: Massimo | H8: Sanremo / Taggia / S.Lorenzo | I8: =COUNTIFS(Registro!$T$5:$T$804,H8,Registro!$A$5:$A$804,">="&DATE(2026,1,1)) -> 14 | J8: 0
A9: RVS Polisportiva | B9: Sanremo palestra Villa Citera | C9: Striscione | D9: 250 | E9: 2024/2025 | F9: Messo – pagato 300 € nel 2026 | G9: Massimo | H9: Sanremo / Taggia / S.Lorenzo | I9: =COUNTIFS(Registro!$T$5:$T$804,H9,Registro!$A$5:$A$804,">="&DATE(2026,1,1)) -> 14 | J9: 0
A10: Imperia Volley | B10: Imperia (in auto da consegnare) | C10: Striscione 2x1 | D10: 300 | E10: 2025/2026 | F10: Da approvare – da pagare 2025 e 2026 | G10: Massimo | H10: Imperia | I10: =COUNTIFS(Registro!$T$5:$T$804,H10,Registro!$A$5:$A$804,">="&DATE(2026,1,1)) -> 8 | J10: 0
A11: Campo Sportivo Borghetto S.S. | B11: Borghetto S.S. | C11: Striscione da prendere | D11: 250 | E11: 2024/2025 | F11: DA METTERE – fermo, non pagato | G11: Sergio Val | H11: Loano / Borghetto / Pietra | I11: =COUNTIFS(Registro!$T$5:$T$804,H11,Registro!$A$5:$A$804,">="&DATE(2026,1,1)) -> 16 | J11: 0
A12: Campo Sportivo Loano | B12: Loano | C12: Striscioni 2x1 nuovi | D12: 250 | E12: 2024/2025 | F12: Da mettere/approvare (+ ritiro 4 big bag macerie in cambio) | G12: Andrea Bac | H12: Loano / Borghetto / Pietra | I12: =COUNTIFS(Registro!$T$5:$T$804,H12,Registro!$A$5:$A$804,">="&DATE(2026,1,1)) -> 16 | J12: 0
A13: ASD Ranzi | B13: Sagra Ranzi (Pietra Ligure) | C13: Provvisorio | E13: 2025/2026 | F13: Riportato Baccino | G13: Andrea Bac | H13: Loano / Borghetto / Pietra | I13: =COUNTIFS(Registro!$T$5:$T$804,H13,Registro!$A$5:$A$804,">="&DATE(2026,1,1)) -> 16 | J13: 0
A14: ASD Pontelungo | B14: Stadio Albenga-Pontelungo | C14: Striscione 5x3 forato GRANDE | D14: 5000 | E14: ott 2025–2027 | F14: Da concordare: 5.000 € per 3 anni a rate | G14: Massimo | H14: Albenga | I14: =COUNTIFS(Registro!$T$5:$T$804,H14,Registro!$A$5:$A$804,">="&DATE(2026,1,1)) -> 4 | J14: 0
A15: V.A.L. | B15: Cisano sul Neva | C15: Striscione 5x3 nuovo | E15: 2025/2026 | F15: In essere – da fare Sergio | G15: Sergio Val | H15: Cisano (V.A.L.) | I15: =COUNTIFS(Registro!$T$5:$T$804,H15,Registro!$A$5:$A$804,">="&DATE(2026,1,1)) -> 0 | J15: 0
A16: Corderia Nazionale | B16: Genova | C16: — | E16: dal 01/09/2024 | F16: Chiuso – 5% su eventuali lavori | G16: Massimo | H16: Genova | I16: =COUNTIFS(Registro!$T$5:$T$804,H16,Registro!$A$5:$A$804,">="&DATE(2026,1,1)) -> 7 | J16: 0
A17: Aut. Porto Sestri Ponente | B17: Genova aeroporto | C17: Cartellone fisso + volantino + online | D17: 1200 | E17: annuale | F17: Stato non indicato | G17: — | H17: Genova | I17: =COUNTIFS(Registro!$T$5:$T$804,H17,Registro!$A$5:$A$804,">="&DATE(2026,1,1)) -> 7 | J17: 0
A18: CIBRA | B18: Coop Imperia | C18: Cartellone | E18: 2025 | F18: Approvata – in essere | G18: Kikko | H18: Imperia | I18: =COUNTIFS(Registro!$T$5:$T$804,H18,Registro!$A$5:$A$804,">="&DATE(2026,1,1)) -> 8 | J18: 0
A19: CIBRA | B19: Coop Sestri Ponente + Coop Pegli (Genova) | C19: 2 cartelloni monofacciali | D19: 2185 | E19: 2025–2030 | F19: In essere (contratto 26/02/2025) | G19: Kikko / Pasini | H19: Genova | I19: =COUNTIFS(Registro!$T$5:$T$804,H19,Registro!$A$5:$A$804,">="&DATE(2026,1,1)) -> 7 | J19: 0
A20: Italiaonline PgCasa + Google Ads | B20: Imperia, Savona, Genova | C20: Campagna digitale | D20: 3700 | E20: 2025 | F20: Da riapprovare (vedi contratto 2026: 7.999,94 €) | G20: Massimo / Kikko | H20: Zone senza striscioni/cartelloni | I20: vedi foglio Canali | J20: 0
A22: Totale striscioni campi sportivi (da elenco) | D22: =SUM(D5:D14) -> 7300
A23: Nota: Pontelungo (5.000 €) è su 3 anni; molti importi sono 'da pagare' o 'da approvare'.
A26: Chiamate 2026 per zona e provenienza dichiarata
A27: Zona | B27: Italiaonline | C27: PgCasa (Italiaonline) | D27: Internet | E27: Passaparola | F27: Altre | G27: Totale | H27: Servizio più richiesto
A28: Sanremo / Taggia / S.Lorenzo | B28: =COUNTIFS(Registro!$T$5:$T$804,$A28,Registro!$B$5:$B$804,"Italiaonline",Registro!$A$5:$A$804,">="&DATE(2026,1,1)) -> 4 | C28: =COUNTIFS(Registro!$T$5:$T$804,$A28,Registro!$B$5:$B$804,"PgCasa (Italiaonline)",Registro!$A$5:$A$804,">="&DATE(2026,1,1)) -> 3 | D28: =COUNTIFS(Registro!$T$5:$T$804,$A28,Registro!$B$5:$B$804,"Internet",Registro!$A$5:$A$804,">="&DATE(2026,1,1)) -> 0 | E28: =COUNTIFS(Registro!$T$5:$T$804,$A28,Registro!$B$5:$B$804,"Passaparola",Registro!$A$5:$A$804,">="&DATE(2026,1,1)) -> 7 | F28: =G28-SUM(B28:E28) -> 0 | G28: =COUNTIFS(Registro!$T$5:$T$804,$A28,Registro!$A$5:$A$804,">="&DATE(2026,1,1)) -> 14 | H28: Bonifiche (7 su 14)
A29: Imperia | B29: =COUNTIFS(Registro!$T$5:$T$804,$A29,Registro!$B$5:$B$804,"Italiaonline",Registro!$A$5:$A$804,">="&DATE(2026,1,1)) -> 1 | C29: =COUNTIFS(Registro!$T$5:$T$804,$A29,Registro!$B$5:$B$804,"PgCasa (Italiaonline)",Registro!$A$5:$A$804,">="&DATE(2026,1,1)) -> 1 | D29: =COUNTIFS(Registro!$T$5:$T$804,$A29,Registro!$B$5:$B$804,"Internet",Registro!$A$5:$A$804,">="&DATE(2026,1,1)) -> 4 | E29: =COUNTIFS(Registro!$T$5:$T$804,$A29,Registro!$B$5:$B$804,"Passaparola",Registro!$A$5:$A$804,">="&DATE(2026,1,1)) -> 2 | F29: =G29-SUM(B29:E29) -> 0 | G29: =COUNTIFS(Registro!$T$5:$T$804,$A29,Registro!$A$5:$A$804,">="&DATE(2026,1,1)) -> 8 | H29: Bonifiche (3 su 8)
A30: Loano / Borghetto / Pietra | B30: =COUNTIFS(Registro!$T$5:$T$804,$A30,Registro!$B$5:$B$804,"Italiaonline",Registro!$A$5:$A$804,">="&DATE(2026,1,1)) -> 2 | C30: =COUNTIFS(Registro!$T$5:$T$804,$A30,Registro!$B$5:$B$804,"PgCasa (Italiaonline)",Registro!$A$5:$A$804,">="&DATE(2026,1,1)) -> 1 | D30: =COUNTIFS(Registro!$T$5:$T$804,$A30,Registro!$B$5:$B$804,"Internet",Registro!$A$5:$A$804,">="&DATE(2026,1,1)) -> 1 | E30: =COUNTIFS(Registro!$T$5:$T$804,$A30,Registro!$B$5:$B$804,"Passaparola",Registro!$A$5:$A$804,">="&DATE(2026,1,1)) -> 10 | F30: =G30-SUM(B30:E30) -> 2 | G30: =COUNTIFS(Registro!$T$5:$T$804,$A30,Registro!$A$5:$A$804,">="&DATE(2026,1,1)) -> 16 | H30: Disinfestazione (4 su 16)
A31: Albenga | B31: =COUNTIFS(Registro!$T$5:$T$804,$A31,Registro!$B$5:$B$804,"Italiaonline",Registro!$A$5:$A$804,">="&DATE(2026,1,1)) -> 1 | C31: =COUNTIFS(Registro!$T$5:$T$804,$A31,Registro!$B$5:$B$804,"PgCasa (Italiaonline)",Registro!$A$5:$A$804,">="&DATE(2026,1,1)) -> 0 | D31: =COUNTIFS(Registro!$T$5:$T$804,$A31,Registro!$B$5:$B$804,"Internet",Registro!$A$5:$A$804,">="&DATE(2026,1,1)) -> 0 | E31: =COUNTIFS(Registro!$T$5:$T$804,$A31,Registro!$B$5:$B$804,"Passaparola",Registro!$A$5:$A$804,">="&DATE(2026,1,1)) -> 3 | F31: =G31-SUM(B31:E31) -> 0 | G31: =COUNTIFS(Registro!$T$5:$T$804,$A31,Registro!$A$5:$A$804,">="&DATE(2026,1,1)) -> 4 | H31: Bonifiche (2 su 4)
A32: Genova | B32: =COUNTIFS(Registro!$T$5:$T$804,$A32,Registro!$B$5:$B$804,"Italiaonline",Registro!$A$5:$A$804,">="&DATE(2026,1,1)) -> 0 | C32: =COUNTIFS(Registro!$T$5:$T$804,$A32,Registro!$B$5:$B$804,"PgCasa (Italiaonline)",Registro!$A$5:$A$804,">="&DATE(2026,1,1)) -> 0 | D32: =COUNTIFS(Registro!$T$5:$T$804,$A32,Registro!$B$5:$B$804,"Internet",Registro!$A$5:$A$804,">="&DATE(2026,1,1)) -> 3 | E32: =COUNTIFS(Registro!$T$5:$T$804,$A32,Registro!$B$5:$B$804,"Passaparola",Registro!$A$5:$A$804,">="&DATE(2026,1,1)) -> 3 | F32: =G32-SUM(B32:E32) -> 1 | G32: =COUNTIFS(Registro!$T$5:$T$804,$A32,Registro!$A$5:$A$804,">="&DATE(2026,1,1)) -> 7 | H32: Da Specificare (5 su 7)
A33: Cisano (V.A.L.) | B33: =COUNTIFS(Registro!$T$5:$T$804,$A33,Registro!$B$5:$B$804,"Italiaonline",Registro!$A$5:$A$804,">="&DATE(2026,1,1)) -> 0 | C33: =COUNTIFS(Registro!$T$5:$T$804,$A33,Registro!$B$5:$B$804,"PgCasa (Italiaonline)",Registro!$A$5:$A$804,">="&DATE(2026,1,1)) -> 0 | D33: =COUNTIFS(Registro!$T$5:$T$804,$A33,Registro!$B$5:$B$804,"Internet",Registro!$A$5:$A$804,">="&DATE(2026,1,1)) -> 0 | E33: =COUNTIFS(Registro!$T$5:$T$804,$A33,Registro!$B$5:$B$804,"Passaparola",Registro!$A$5:$A$804,">="&DATE(2026,1,1)) -> 0 | F33: =G33-SUM(B33:E33) -> 0 | G33: =COUNTIFS(Registro!$T$5:$T$804,$A33,Registro!$A$5:$A$804,">="&DATE(2026,1,1)) -> 0 | H33: —
A34: Zone senza striscioni/cartelloni | B34: =COUNTIFS(Registro!$T$5:$T$804,$A34,Registro!$B$5:$B$804,"Italiaonline",Registro!$A$5:$A$804,">="&DATE(2026,1,1)) -> 32 | C34: =COUNTIFS(Registro!$T$5:$T$804,$A34,Registro!$B$5:$B$804,"PgCasa (Italiaonline)",Registro!$A$5:$A$804,">="&DATE(2026,1,1)) -> 6 | D34: =COUNTIFS(Registro!$T$5:$T$804,$A34,Registro!$B$5:$B$804,"Internet",Registro!$A$5:$A$804,">="&DATE(2026,1,1)) -> 29 | E34: =COUNTIFS(Registro!$T$5:$T$804,$A34,Registro!$B$5:$B$804,"Passaparola",Registro!$A$5:$A$804,">="&DATE(2026,1,1)) -> 58 | F34: =G34-SUM(B34:E34) -> 5 | G34: =COUNTIFS(Registro!$T$5:$T$804,$A34,Registro!$A$5:$A$804,">="&DATE(2026,1,1)) -> 130 | H34: Rifiuti (33 su 130)
A36: CONCLUSIONE
A37: 1) Nel registro chiamate 2026 NESSUN contatto è segnato come arrivato da striscione o cartellone: la reception non ha questa voce in 'Provenienza'.
A38: 2) Dalle zone con striscioni (Sanremo-Taggia, Imperia, Loano-Borghetto-Pietra, Albenga) arrivano chiamate, ma quasi tutte dichiarate 'Passaparola', 'Italiaonline' o 'Internet'.
A39: 3) Genova (2 cartelloni CIBRA, circa 2.185 €/anno): 7 chiamate, 3 dal sito e 3 da passaparola, nessuna dal cartellone.
A40: 4) Da fare subito: aggiungere in reception la provenienza 'STRISCIONE/CARTELLONE' + chiedere sempre 'dove ci ha visto?'. Senza questo dato non si può misurare il ritorno degli striscioni.
A41: 5) Prima di firmare Pontelungo (5.000 € in 3 anni) conviene 3 mesi di prova con la domanda in reception.

Sheet Rubriche web
A1: Contatti dal modulo web (rubriche Italiaonline) – confronto con il Registro
A2: File: rubrica Contatti sito dal 2021, Rubrica IOL al 29/10/2025, Backup rubrica 17/08/2026. 'Nel registro?' si aggiorna da solo cercando l'email nel Registro
A4: Data | B4: Mese | C4: Rubrica | D4: Nome | E4: Cognome | F4: Telefono (dal CSV) | G4: Email | H4: Newsletter | I4: Nel registro? | K4: Riepilogo per anno | L4: Contatti web | M4: Media al mese
A5: 46230 | B5: =TEXT(A5,"yyyy-mm") -> 2026-07 | C5: IOL 2026 | D5: SIMONE | E5: CONTI | F5: 3,93355E+11 | G5: simonecontig@gmail.com | H5: no | I5: =IF(G5="","",IF(COUNTIF(Registro!$G$5:$G$804,G5)>0,"SI","NO")) -> NO | K5: 2021 (da apr) | L5: =COUNTIFS($A$5:$A$293,">="&DATE(2021,1,1),$A$5:$A$293,"<"&DATE(2022,1,1)) -> 13 | M5: =L5/9 -> 1.4444444
A6: 46219 | B6: =TEXT(A6,"yyyy-mm") -> 2026-07 | C6: IOL 2026 | D6: Alessandro | E6: Averla | F6: 3,90198E+11 | G6: info@averla.it | H6: sì | I6: =IF(G6="","",IF(COUNTIF(Registro!$G$5:$G$804,G6)>0,"SI","NO")) -> SI | K6: 2022 | L6: =COUNTIFS($A$5:$A$293,">="&DATE(2022,1,1),$A$5:$A$293,"<"&DATE(2023,1,1)) -> 24 | M6: =L6/12 -> 2
A7: 46205 | B7: =TEXT(A7,"yyyy-mm") -> 2026-07 | C7: IOL 2026 | D7: Monica | E7: Molecca | F7: 3,93477E+11 | G7: monicavale1972@libero.it | H7: no | I7: =IF(G7="","",IF(COUNTIF(Registro!$G$5:$G$804,G7)>0,"SI","NO")) -> NO | K7: 2023 | L7: =COUNTIFS($A$5:$A$293,">="&DATE(2023,1,1),$A$5:$A$293,"<"&DATE(2024,1,1)) -> 23 | M7: =L7/12 -> 1.9166667
A8: 46190 | B8: =TEXT(A8,"yyyy-mm") -> 2026-06 | C8: IOL 2026 | D8: INOX | E8: SIGNAL | F8: 39019801737 | G8: inoxsignalsrl@gmail.com | H8: sì | I8: =IF(G8="","",IF(COUNTIF(Registro!$G$5:$G$804,G8)>0,"SI","NO")) -> NO | K8: 2024 | L8: =COUNTIFS($A$5:$A$293,">="&DATE(2024,1,1),$A$5:$A$293,"<"&DATE(2025,1,1)) -> 78 | M8: =L8/12 -> 6.5
A9: 46187 | B9: =TEXT(A9,"yyyy-mm") -> 2026-06 | C9: IOL 2026 | D9: umberto | E9: di sario | F9: 3,93277E+11 | G9: desse10@virgilio.it | H9: sì | I9: =IF(G9="","",IF(COUNTIF(Registro!$G$5:$G$804,G9)>0,"SI","NO")) -> NO | K9: 2025 (fino a ott) | L9: =COUNTIFS($A$5:$A$293,">="&DATE(2025,1,1),$A$5:$A$293,"<"&DATE(2026,1,1)) -> 121 | M9: =L9/10 -> 12.1
A10: 46178 | B10: =TEXT(A10,"yyyy-mm") -> 2026-06 | C10: IOL 2026 | D10: Stefan | E10: Politzka | F10: 4,91793E+11 | G10: stefan_politzka@posteo.de | H10: no | I10: =IF(G10="","",IF(COUNTIF(Registro!$G$5:$G$804,G10)>0,"SI","NO")) -> NO | K10: 2026 (mar–lug) | L10: =COUNTIFS($A$5:$A$293,">="&DATE(2026,1,1),$A$5:$A$293,"<"&DATE(2027,1,1)) -> 30 | M10: =L10/5 -> 6
A11: 46171 | B11: =TEXT(A11,"yyyy-mm") -> 2026-05 | C11: IOL 2026 | D11: Chiara | E11: Orlandini | F11: 3,93665E+11 | G11: chiara.or.999@gmail.com | H11: no | I11: =IF(G11="","",IF(COUNTIF(Registro!$G$5:$G$804,G11)>0,"SI","NO")) -> NO
A12: 46171 | B12: =TEXT(A12,"yyyy-mm") -> 2026-05 | C12: IOL 2026 | D12: Stefania | E12: Pisano | F12: 3,93342E+11 | G12: ste.pi72@yahoo.it | H12: sì | I12: =IF(G12="","",IF(COUNTIF(Registro!$G$5:$G$804,G12)>0,"SI","NO")) -> NO | K12: Contatti web 2026 | L12: =COUNTIFS($A$5:$A$293,">="&DATE(2026,1,1)) -> 30
A13: 46170 | B13: =TEXT(A13,"yyyy-mm") -> 2026-05 | C13: IOL 2026 | D13: ChangHong | E13: S.R.L | F13: 3,93384E+11 | G13: chdstudio2026@gmail.com | H13: no | I13: =IF(G13="","",IF(COUNTIF(Registro!$G$5:$G$804,G13)>0,"SI","NO")) -> NO | K13: …di cui presenti nel Registro | L13: =COUNTIFS($A$5:$A$293,">="&DATE(2026,1,1),$I$5:$I$293,"SI") -> 13
A14: 46168 | B14: =TEXT(A14,"yyyy-mm") -> 2026-05 | C14: IOL 2026 | D14: Giovanni | E14: Denert | F14: 3,93467E+11 | G14: giovanni.denert@gmail.com | H14: no | I14: =IF(G14="","",IF(COUNTIF(Registro!$G$5:$G$804,G14)>0,"SI","NO")) -> NO | K14: …NON presenti nel Registro | L14: =L12-L13 -> 17
A15: 46155 | B15: =TEXT(A15,"yyyy-mm") -> 2026-05 | C15: IOL 2026 | D15: Alessandra | E15: Minelli | F15: 3,93409E+11 | G15: minelli.amministrazioni@gmail.com | H15: no | I15: =IF(G15="","",IF(COUNTIF(Registro!$G$5:$G$804,G15)>0,"SI","NO")) -> NO
A16: 46152 | B16: =TEXT(A16,"yyyy-mm") -> 2026-05 | C16: IOL 2026 | D16: Alessandro | E16: Para | F16: 3,93478E+11 | G16: para.alessandro@libero.it | H16: no | I16: =IF(G16="","",IF(COUNTIF(Registro!$G$5:$G$804,G16)>0,"SI","NO")) -> SI | K16: Nota: i CSV hanno i telefoni in formato scientifico (es. 3,93385E+11): cifre perse. Esportare di nuovo dall'area clienti Italiaonline aprendo il CSV come testo.
A17: 46149 | B17: =TEXT(A17,"yyyy-mm") -> 2026-05 | C17: IOL 2026 | D17: Adriana | E17: Popolo | F17: 3,93385E+11 | G17: adrianapopolo02@gmail.com | H17: no | I17: =IF(G17="","",IF(COUNTIF(Registro!$G$5:$G$804,G17)>0,"SI","NO")) -> SI | K17: Manca il periodo nov 2025 – feb 2026 (nessuna rubrica esportata).
A18: 46145 | B18: =TEXT(A18,"yyyy-mm") -> 2026-05 | C18: IOL 2026 | D18: Ireni | E18: Oliveira | F18: 3,9327E+11 | G18: irenibarbosa.ib@gmail.com | H18: sì | I18: =IF(G18="","",IF(COUNTIF(Registro!$G$5:$G$804,G18)>0,"SI","NO")) -> NO
A19: 46139 | B19: =TEXT(A19,"yyyy-mm") -> 2026-04 | C19: IOL 2026 | D19: Andrea | E19: Magni | F19: 3,93356E+11 | G19: andreamagni@me.com | H19: no | I19: =IF(G19="","",IF(COUNTIF(Registro!$G$5:$G$804,G19)>0,"SI","NO")) -> NO
A20: 46137 | B20: =TEXT(A20,"yyyy-mm") -> 2026-04 | C20: IOL 2026 | D20: ELDA | E20: CARAGNO | F20: 3,93394E+11 | G20: cfcarni@libero.it | H20: sì | I20: =IF(G20="","",IF(COUNTIF(Registro!$G$5:$G$804,G20)>0,"SI","NO")) -> NO
A21: 46137 | B21: =TEXT(A21,"yyyy-mm") -> 2026-04 | C21: IOL 2026 | D21: roberto | E21: locatelli | F21: 3,93386E+11 | G21: robiloca68@gmail.com | H21: sì | I21: =IF(G21="","",IF(COUNTIF(Registro!$G$5:$G$804,G21)>0,"SI","NO")) -> NO
A22: 46136 | B22: =TEXT(A22,"yyyy-mm") -> 2026-04 | C22: IOL 2026 | D22: Martin | E22: Nilsson | F22: 46768653193 | G22: martin.nilsson7210@gmail.com.com | H22: no | I22: =IF(G22="","",IF(COUNTIF(Registro!$G$5:$G$804,G22)>0,"SI","NO")) -> NO
A23: 46135 | B23: =TEXT(A23,"yyyy-mm") -> 2026-04 | C23: IOL 2026 | D23: Fulvio Francesco | E23: Palmieri | F23: 3,93487E+11 | G23: fulvioingpalmieri@libero.it | H23: sì | I23: =IF(G23="","",IF(COUNTIF(Registro!$G$5:$G$804,G23)>0,"SI","NO")) -> NO
A24: 46134 | B24: =TEXT(A24,"yyyy-mm") -> 2026-04 | C24: IOL 2026 | D24: Emily | E24: Mirch | F24: 39347369777 | G24: mirchemily@gmail.com | H24: sì | I24: =IF(G24="","",IF(COUNTIF(Registro!$G$5:$G$804,G24)>0,"SI","NO")) -> SI
A25: 46134 | B25: =TEXT(A25,"yyyy-mm") -> 2026-04 | C25: IOL 2026 | D25: Ettore | E25: Carpentieri | F25: 3,93406E+11 | G25: ettore.carpentieri@gmail.com | H25: no | I25: =IF(G25="","",IF(COUNTIF(Registro!$G$5:$G$804,G25)>0,"SI","NO")) -> SI
A26: 46133 | B26: =TEXT(A26,"yyyy-mm") -> 2026-04 | C26: IOL 2026 | D26: Lucrezia | E26: Fasolo | F26: 3,93202E+11 | G26: lucreziafasolo94@gmail.com | H26: sì | I26: =IF(G26="","",IF(COUNTIF(Registro!$G$5:$G$804,G26)>0,"SI","NO")) -> SI
A27: 46132 | B27: =TEXT(A27,"yyyy-mm") -> 2026-04 | C27: IOL 2026 | D27: Anna | E27: Marangon | F27: 3,93287E+11 | G27: maria.m48@icloud.com | H27: no | I27: =IF(G27="","",IF(COUNTIF(Registro!$G$5:$G$804,G27)>0,"SI","NO")) -> SI
A28: 46132 | B28: =TEXT(A28,"yyyy-mm") -> 2026-04 | C28: IOL 2026 | D28: Felisia | E28: D’Andrea | F28: 3,93407E+11 | G28: felisiadandrea@libero.it | H28: no | I28: =IF(G28="","",IF(COUNTIF(Registro!$G$5:$G$804,G28)>0,"SI","NO")) -> SI
A29: 46127 | B29: =TEXT(A29,"yyyy-mm") -> 2026-04 | C29: IOL 2026 | D29: Riccardo | E29: Campi | F29: 3,93495E+11 | G29: rikic1979@gmail.com | H29: no | I29: =IF(G29="","",IF(COUNTIF(Registro!$G$5:$G$804,G29)>0,"SI","NO")) -> NO
... A293: 44316 | B293: =TEXT(A293,"yyyy-mm") -> 2021-04 | C293: Sito 2021-2024 | D293: anna | E293: cusati | F293: 3901995488 | G293: info@residencelavignetta.it | H293: no | I293: =IF(G293="","",IF(COUNTIF(Registro!$G$5:$G$804,G293)>0,"SI","NO")) -> NO

Sheet Bilancio e servizi
A1: Ricavi per servizio 2023-2025 (bilancio) e richieste 2026 (registro)
A2: Fonte: Bilancio comparato Servizi Ecologici 23-24-25, conti 58/05/xxx. Contatti 2026 = righe del Registro per area/servizio
A4: Voce di ricavo (bilancio) | B4: 2023 € | C4: 2024 € | D4: 2025 € | E4: Var. 2025 su 2024 | F4: Area | G4: Contatti 2026 nel registro (area)
A5: Disostruzione canaljet reti/fosse | B5: 772916.86 | C5: 929156.23 | D5: 792167.46 | E5: =IFERROR(D5/C5-1,"") -> -0.14743352 | F5: SPURGHI E RETI | G5: =COUNTIFS(Registro!$J$5:$J$804,F5,Registro!$A$5:$A$804,">="&DATE(2026,1,1)) -> 28
A6: Ispezioni televisive | B6: 58293.86 | C6: 57215.81 | D6: 44209.63 | E6: =IFERROR(D6/C6-1,"") -> -0.22731794 | F6: SPURGHI E RETI | G6: =COUNTIFS(Registro!$J$5:$J$804,F6,Registro!$A$5:$A$804,">="&DATE(2026,1,1)) -> 28
A7: Posizionamento e ritiro cassoni | B7: 451265.44 | C7: 281562.02 | D7: 332478.44 | E7: =IFERROR(D7/C7-1,"") -> 0.18083554 | F7: RIFIUTI | G7: =COUNTIFS(Registro!$J$5:$J$804,F7,Registro!$A$5:$A$804,">="&DATE(2026,1,1)) -> 38
A8: Smaltimento rifiuti liquidi | B8: 315159.57 | C8: 242199.58 | D8: 213118.59 | E8: =IFERROR(D8/C8-1,"") -> -0.12007036 | F8: RIFIUTI | G8: =COUNTIFS(Registro!$J$5:$J$804,F8,Registro!$A$5:$A$804,">="&DATE(2026,1,1)) -> 38
A9: Smaltimento rifiuti solidi | B9: 315000.33 | C9: 225097.09 | D9: 207869.67 | E9: =IFERROR(D9/C9-1,"") -> -0.076533286 | F9: RIFIUTI | G9: =COUNTIFS(Registro!$J$5:$J$804,F9,Registro!$A$5:$A$804,">="&DATE(2026,1,1)) -> 38
A10: Smaltimento inerti | B10: 319556.84 | C10: 43442.59 | D10: 59058.42 | E10: =IFERROR(D10/C10-1,"") -> 0.359459 | F10: RIFIUTI | G10: =COUNTIFS(Registro!$J$5:$J$804,F10,Registro!$A$5:$A$804,">="&DATE(2026,1,1)) -> 38
A11: Analisi rifiuti solidi e liquidi | B11: 22135 | C11: 26370 | D11: 31140 | E11: =IFERROR(D11/C11-1,"") -> 0.18088737 | F11: DA SPECIFICARE | G11: =COUNTIFS(Registro!$J$5:$J$804,F11,Registro!$A$5:$A$804,">="&DATE(2026,1,1)) -> 31
A12: Analisi, smaltimento e incapsulamento amianto | B12: 383945.8 | C12: 342170.88 | D12: 228926.1 | E12: =IFERROR(D12/C12-1,"") -> -0.33095972 | F12: BONIFICHE | G12: =COUNTIFS(Registro!$J$5:$J$804,F12,Registro!$A$5:$A$804,">="&DATE(2026,1,1)) -> 38
A13: Censimento amianto | B13: 8540 | C13: 1280 | D13: 48202.8 | E13: =IFERROR(D13/C13-1,"") -> 36.658437 | F13: BONIFICHE | G13: =COUNTIFS(Registro!$J$5:$J$804,F13,Registro!$A$5:$A$804,">="&DATE(2026,1,1)) -> 38
A14: Analisi amianto | B14: 11180 | C14: 7650 | D14: 1460 | E14: =IFERROR(D14/C14-1,"") -> -0.80915033 | F14: BONIFICHE | G14: =COUNTIFS(Registro!$J$5:$J$804,F14,Registro!$A$5:$A$804,">="&DATE(2026,1,1)) -> 38
A15: Bonifiche ambientali | B15: 39634 | C15: 295400.25 | D15: 94274.44 | E15: =IFERROR(D15/C15-1,"") -> -0.68085863 | F15: BONIFICHE | G15: =COUNTIFS(Registro!$J$5:$J$804,F15,Registro!$A$5:$A$804,">="&DATE(2026,1,1)) -> 38
A16: Disinfestazioni e derattizzazioni | B16: 139478.33 | C16: 126183.27 | D16: 140242.37 | E16: =IFERROR(D16/C16-1,"") -> 0.1114181 | F16: DISINFESTAZIONE | G16: =COUNTIFS(Registro!$J$5:$J$804,F16,Registro!$A$5:$A$804,">="&DATE(2026,1,1)) -> 30
... A21: Noleggio bagni chimici | B21: 51093.4 | C21: 34597.36 | D21: 1450 | E21: =IFERROR(D21/C21-1,"") -> -0.95808929 | F21: SPURGHI E RETI | G21: =COUNTIFS(Registro!$J$5:$J$804,F21,Registro!$A$5:$A$804,">="&DATE(2026,1,1)) -> 28
A22: Vendite diverse / altro | B22: 102304.28 | C22: 64663.71 | D22: 76329.29 | E22: =IFERROR(D22/C22-1,"") -> 0.18040382
A23: TOTALE ricavi delle vendite (bilancio) | B23: 3030649.5 | C23: 2721837.2 | D23: 2340723.8 | E23: =D23/C23-1 -> -0.14002065
A24: Somma righe sopra (controllo) | B24: =SUM(B5:B22) -> 3030649.5 | C24: =SUM(C5:C22) -> 2721837.2 | D24: =SUM(D5:D22) -> 2340723.8
A25: Utile d'esercizio | B25: 56275.46 | C25: 86005 | D25: 2075.89
A28: Richieste 2026 per area (registro) vs ricavi 2025
A29: Area | B29: Ricavi 2025 € (voci sopra) | C29: Contatti 2026 | D29: di cui Italiaonline + PgCasa
A30: SPURGHI E RETI | B30: =SUMIF($F$5:$F$22,A30,$D$5:$D$22) -> 837827.09 | C30: =COUNTIFS(Registro!$J$5:$J$804,A30,Registro!$A$5:$A$804,">="&DATE(2026,1,1)) -> 28 | D30: =COUNTIFS(Registro!$J$5:$J$804,A30,Registro!$B$5:$B$804,"Italiaonline",Registro!$A$5:$A$804,">="&DATE(2026,1,1))+COUNTIFS(Registro!$J$5:$J$804,A30,Registro!$B$5:$B$804,"PgCasa (Italiaonline)",Registro!$A$5:$A$804,">="&DATE(2026,1,1)) -> 10
A31: RIFIUTI | B31: =SUMIF($F$5:$F$22,A31,$D$5:$D$22) -> 812525.12 | C31: =COUNTIFS(Registro!$J$5:$J$804,A31,Registro!$A$5:$A$804,">="&DATE(2026,1,1)) -> 38 | D31: =COUNTIFS(Registro!$J$5:$J$804,A31,Registro!$B$5:$B$804,"Italiaonline",Registro!$A$5:$A$804,">="&DATE(2026,1,1))+COUNTIFS(Registro!$J$5:$J$804,A31,Registro!$B$5:$B$804,"PgCasa (Italiaonline)",Registro!$A$5:$A$804,">="&DATE(2026,1,1)) -> 8
A32: BONIFICHE | B32: =SUMIF($F$5:$F$22,A32,$D$5:$D$22) -> 372863.34 | C32: =COUNTIFS(Registro!$J$5:$J$804,A32,Registro!$A$5:$A$804,">="&DATE(2026,1,1)) -> 38 | D32: =COUNTIFS(Registro!$J$5:$J$804,A32,Registro!$B$5:$B$804,"Italiaonline",Registro!$A$5:$A$804,">="&DATE(2026,1,1))+COUNTIFS(Registro!$J$5:$J$804,A32,Registro!$B$5:$B$804,"PgCasa (Italiaonline)",Registro!$A$5:$A$804,">="&DATE(2026,1,1)) -> 10
A33: DISINFESTAZIONE | B33: =SUMIF($F$5:$F$22,A33,$D$5:$D$22) -> 140242.37 | C33: =COUNTIFS(Registro!$J$5:$J$804,A33,Registro!$A$5:$A$804,">="&DATE(2026,1,1)) -> 30 | D33: =COUNTIFS(Registro!$J$5:$J$804,A33,Registro!$B$5:$B$804,"Italiaonline",Registro!$A$5:$A$804,">="&DATE(2026,1,1))+COUNTIFS(Registro!$J$5:$J$804,A33,Registro!$B$5:$B$804,"PgCasa (Italiaonline)",Registro!$A$5:$A$804,">="&DATE(2026,1,1)) -> 9
A34: IGIENE IMPIANTI | B34: =SUMIF($F$5:$F$22,A34,$D$5:$D$22) -> 13540 | C34: =COUNTIFS(Registro!$J$5:$J$804,A34,Registro!$A$5:$A$804,">="&DATE(2026,1,1)) -> 14 | D34: =COUNTIFS(Registro!$J$5:$J$804,A34,Registro!$B$5:$B$804,"Italiaonline",Registro!$A$5:$A$804,">="&DATE(2026,1,1))+COUNTIFS(Registro!$J$5:$J$804,A34,Registro!$B$5:$B$804,"PgCasa (Italiaonline)",Registro!$A$5:$A$804,">="&DATE(2026,1,1)) -> 7
A35: DA SPECIFICARE | B35: =SUMIF($F$5:$F$22,A35,$D$5:$D$22) -> 87396.56 | C35: =COUNTIFS(Registro!$J$5:$J$804,A35,Registro!$A$5:$A$804,">="&DATE(2026,1,1)) -> 31 | D35: =COUNTIFS(Registro!$J$5:$J$804,A35,Registro!$B$5:$B$804,"Italiaonline",Registro!$A$5:$A$804,">="&DATE(2026,1,1))+COUNTIFS(Registro!$J$5:$J$804,A35,Registro!$B$5:$B$804,"PgCasa (Italiaonline)",Registro!$A$5:$A$804,">="&DATE(2026,1,1)) -> 7

Sheet Registro
A1: Registro contatti e lavori
A2: 184 contatti caricati (168 dal registro chiamate 2026 + 16 PgCasa). Celle gialle da compilare: ESITO e MOTIVO servono per le statistiche
A4: Data | B4: Fonte | C4: Dettaglio fonte | D4: Cliente | E4: Tipo cliente | F4: Telefono | G4: Email | H4: Comune | I4: Prov. | J4: Area servizio | K4: Servizio (dal foglio Servizi) | L4: Richiesta del cliente | M4: Esito | N4: Motivo (se NON PRESO) | O4: Importo preventivo € | P4: Importo lavoro fatto € | Q4: Costo contatto € | R4: Commerciale (cod.) | S4: Note | T4: Zona pubblicità locale
A5: 44823 | B5: PgCasa (Italiaonline) | C5: Richiesta preventivo PgCasa | D5: Alessandro F. | E5: Privato | F5: 3488121357 | G5: aferraro720@gmail.com | H5: Loano | I5: SV | J5: DISINFESTAZIONE | K5: Allontanamento volatili (piccioni, gabbiani) | L5: Allontanamento piccioni/volatili | M5: DA RICONTATTARE | Q5: 5 | S5: esito da verificare | T5: Loano / Borghetto / Pietra
A6: 45187 | B6: PgCasa (Italiaonline) | C6: Richiesta preventivo PgCasa | D6: Giancarlo R. | E6: Privato | F6: 3428016129 | G6: acovasco@yahoo.it | H6: Tovo San Giacomo | I6: SV | J6: SPURGHI E RETI | K6: Canaljet – autospurgo fosse biologiche, fognature, pozzetti, degrassatori | L6: Spurgo tubo acque bianche | M6: DA RICONTATTARE | Q6: 5 | S6: esito da verificare | T6: Zone senza striscioni/cartelloni
A7: 45187 | B7: PgCasa (Italiaonline) | C7: Richiesta preventivo PgCasa | D7: Andrea Z. | E7: Privato | F7: 3313761023 | G7: andrea.zannoli@gmail.com | H7: Camporosso | I7: IM | J7: SPURGHI E RETI | K7: Canaljet – autospurgo fosse biologiche, fognature, pozzetti, degrassatori | L7: Spurgo fossa settica: Fossa settica casa indipendente ~6000 l | M7: DA RICONTATTARE | Q7: 5 | S7: esito da verificare | T7: Zone senza striscioni/cartelloni
A8: 45187 | B8: PgCasa (Italiaonline) | C8: Richiesta preventivo PgCasa | D8: Silvana S. | E8: Azienda / Società | F8: 3356698662 | G8: info@nattadimontetabor.it | H8: Celle Ligure | I8: SV | J8: DISINFESTAZIONE | K8: Derattizzazione, disinfestazione insetti, disinfezione, sanificazione | L8: Derattizzazione | M8: DA RICONTATTARE | Q8: 5 | S8: esito da verificare | T8: Zone senza striscioni/cartelloni
A9: 45224 | B9: PgCasa (Italiaonline) | C9: Richiesta preventivo PgCasa | D9: Valentina B. | E9: Privato | F9: 3466961758 | G9: valentina.bach@uwcad.it | H9: Albisola Superiore | I9: SV | J9: DISINFESTAZIONE | K9: Derattizzazione, disinfestazione insetti, disinfezione, sanificazione | L9: Derattizzazione: Verifica e interventi senza veleno | M9: DA RICONTATTARE | Q9: 5 | S9: esito da verificare | T9: Zone senza striscioni/cartelloni
A10: 46029 | B10: Italiaonline | D10: Tortarolo Guglielmo | E10: Attività / Turismo | F10: 3663699474 | G10: guglielmo@hotel-sanmichele.it | H10: Celle Ligure | I10: SV | J10: IGIENE IMPIANTI | K10: Pulizia canne fumarie (spazzacamino) | L10: Ispezione TV canne fumarie | M10: DA VERIFICARE | R10: 1 | S10: Registro chiamate 2026 – motivo 'IT CANNE' – tipologia 'Attività' – esito da inserire | T10: Zone senza striscioni/cartelloni
A11: 46030 | B11: Italiaonline | D11: Raffaele Corrado | E11: Privato | F11: 3470732628 | G11: crrrfl93a20@gmail.com | H11: Finale Ligure | I11: SV | J11: IGIENE IMPIANTI | K11: Pulizia canne fumarie (spazzacamino) | L11: Ispezione TV canne fumarie | M11: DA VERIFICARE | R11: 34 | S11: Registro chiamate 2026 – motivo 'IT CANNE' – tipologia 'Privato' – esito da inserire | T11: Zone senza striscioni/cartelloni
A12: 46030 | B12: Italiaonline | D12: Furlanetto Davide | E12: Privato | F12: 3397972961 | G12: geom.davidefurla@libero.it | H12: Andora | I12: SV | J12: BONIFICHE | K12: Rimozione e smaltimento amianto – eternit | L12: Amianto | M12: DA VERIFICARE | R12: 11 | S12: Registro chiamate 2026 – motivo 'AMIANTO' – tipologia 'Privato' – esito da inserire | T12: Zone senza striscioni/cartelloni
A13: 46030 | B13: Italiaonline | D13: D'Aquino Mario | E13: Privato | F13: 3357352754 | G13: bymario@libero.it | H13: Albisola Marina | I13: SV | J13: IGIENE IMPIANTI | K13: Pulizia canne fumarie (spazzacamino) | L13: Ispezione TV canne fumarie | M13: DA VERIFICARE | R13: 4 | S13: Registro chiamate 2026 – motivo 'IT CANNE' – tipologia 'Privato' – esito da inserire | T13: Zone senza striscioni/cartelloni
A14: 46033 | B14: Internet | C14: Nostro Sito | D14: Garzino Alberto | E14: Impresa edile / Artigiano | F14: 3391218326 | G14: alberto.garzino@virgilio.it | H14: Spotorno | I14: SV | J14: RIFIUTI | K14: Smaltimento rifiuti pericolosi e non pericolosi | L14: Rifiuti | M14: DA VERIFICARE | R14: 4 | S14: Registro chiamate 2026 – motivo 'RIFIUTI' – tipologia 'Imp. Edile' – esito da inserire | T14: Zone senza striscioni/cartelloni
A15: 46037 | B15: Italiaonline | D15: Domenico Timpano | E15: Privato | F15: 3401426500 | G15: domytim31@gmail.com | H15: Borgio Verezzi | I15: SV | J15: RIFIUTI | K15: Smaltimento rifiuti pericolosi e non pericolosi | L15: Rifiuti | M15: DA VERIFICARE | R15: 4 | S15: Registro chiamate 2026 – motivo 'RIFIUTI' – tipologia 'Privato' – esito da inserire | T15: Zone senza striscioni/cartelloni
A16: 46037 | B16: Italiaonline | D16: Roberto Parodi | E16: Privato | F16: 3929973357 | G16: info@studioparodi.org | H16: Savona | I16: SV | J16: RIFIUTI | K16: Smaltimento rifiuti pericolosi e non pericolosi | L16: Rifiuti | M16: DA VERIFICARE | R16: 4 | S16: Registro chiamate 2026 – motivo 'RIFIUTI' – tipologia 'Privato' – esito da inserire | T16: Zone senza striscioni/cartelloni
A17: 46038 | B17: Internet | C17: Nostro Sito | D17: Melina Alice | E17: Privato | F17: 3470865194 | G17: alice.melina@tim.it | H17: Imperia | I17: IM | J17: BONIFICHE | K17: Rimozione e smaltimento amianto – eternit | L17: Amianto | M17: DA VERIFICARE | R17: 11 | S17: Registro chiamate 2026 – motivo 'AMIANTO' – tipologia 'Privato' – esito da inserire | T17: Imperia
A18: 46041 | B18: Internet | C18: Nostro Sito | D18: Expertise Srl | E18: Azienda / Società | F18: 3498225725 | G18: federica.alesiani@expertise.it | H18: Vado Ligure | I18: SV | J18: DISINFESTAZIONE | K18: Derattizzazione, disinfestazione insetti, disinfezione, sanificazione | L18: Sanificazione | M18: DA VERIFICARE | R18: 4 | S18: Registro chiamate 2026 – motivo 'SANIFICAZI' – tipologia 'Associazione' – esito da inserire | T18: Zone senza striscioni/cartelloni
A19: 46045 | B19: Internet | C19: Nostro Sito | D19: Global Psa | E19: Azienda / Società | F19: 3315718808 | G19: alessandra.raffaele@globalpsa. | H19: Genova | I19: GE | J19: DA SPECIFICARE | L19: Pulizia (specificare: cisterne, facciate, cappe…) | M19: DA VERIFICARE | R19: 34 | S19: Registro chiamate 2026 – motivo 'PULIZ.' – tipologia 'Manutentore' – esito da inserire | T19: Genova
A20: 46045 | B20: Internet | C20: Nostro Sito | D20: Cgg Spa | E20: Impresa edile / Artigiano | F20: 3351835165 | G20: zagarese@gilardi.it | H20: Genova | I20: GE | J20: BONIFICHE | K20: Bonifiche ambientali e discariche abusive | L20: Bonifica | M20: DA VERIFICARE | R20: 34 | S20: Registro chiamate 2026 – motivo 'BONIFICA' – tipologia 'Imp. Edile' – esito da inserire | T20: Genova
A21: 46048 | B21: Italiaonline | D21: Fantini Orazio | E21: Privato | F21: 3471172348 | G21: oraziofan73@gmail.com | H21: Pietra Ligure | I21: SV | J21: DA SPECIFICARE | L21: Analisi (specificare: acque potabili o rifiuti) | M21: DA VERIFICARE | R21: 34 | S21: Registro chiamate 2026 – motivo 'ANALISI' – tipologia 'Privato' – esito da inserire | T21: Loano / Borghetto / Pietra
A22: 46048 | B22: Internet | C22: Nostro Sito | D22: La Giglio Eco Group | E22: Impresa edile / Artigiano | F22: 055414559 | G22: cantieri@giglioecogroup.it | H22: Imperia | I22: IM | J22: BONIFICHE | K22: Rimozione e smaltimento amianto – eternit | L22: Amianto | M22: DA VERIFICARE | R22: 11 | S22: Registro chiamate 2026 – motivo 'AMIANTO' – tipologia 'Imp. Edile' – esito da inserire | T22: Imperia
A23: 46049 | B23: Passaparola | D23: Selvaggi Valerio | E23: Privato | F23: 3402836170 | H23: Cipressa | I23: IM | J23: BONIFICHE | K23: Rimozione e smaltimento amianto – eternit | L23: Amianto | M23: DA VERIFICARE | R23: 11 | S23: Registro chiamate 2026 – motivo 'AMIANTO' – tipologia 'Privato' – esito da inserire | T23: Zone senza striscioni/cartelloni
A24: 46051 | B24: Italiaonline | D24: Rossi Elide | E24: Privato | F24: 3280343380 | G24: rossi_elide@yahoo.com | H24: Xxmiglia | I24: IM | J24: BONIFICHE | K24: Rimozione e smaltimento amianto – eternit | L24: Amianto | M24: DA VERIFICARE | R24: 11 | S24: Registro chiamate 2026 – motivo 'AMIANTO' – tipologia 'Privato' – esito da inserire | T24: Zone senza striscioni/cartelloni
A25: 46054 | B25: PgCasa (Italiaonline) | C25: Richiesta preventivo PgCasa | D25: Fabio L. | E25: Privato | F25: 3911030392 | G25: f.leanzi@gmail.com | H25: Perinaldo | I25: IM | J25: SPURGHI E RETI | K25: Canaljet – autospurgo fosse biologiche, fognature, pozzetti, degrassatori | L25: Svuotamento fossa biologica: Fossa ~2 mq, serve camion piccolo (accesso stretto) | M25: DA RICONTATTARE | Q25: 10 | S25: Risposto 01/02 (Contini) – esito da verificare | T25: Zone senza striscioni/cartelloni
A26: 46056 | B26: Internet | C26: Nostro Sito | D26: Green System Srl | E26: Impresa edile / Artigiano | F26: 3468468539 | G26: utc@greensystemsrl.com | H26: Savona | I26: SV | J26: RIFIUTI | K26: Smaltimento rifiuti pericolosi e non pericolosi | L26: Rifiuti | M26: DA VERIFICARE | R26: 4 | S26: Registro chiamate 2026 – motivo 'RIFIUTI' – tipologia 'Imp. Edile' – esito da inserire | T26: Zone senza striscioni/cartelloni
A27: 46056 | B27: Italiaonline | D27: Feliziani Carlo | E27: Privato | F27: 3397275239 | G27: carlo.felizianitab@gmail.com | H27: Andora | I27: SV | J27: SPURGHI E RETI | K27: Rinnovamento non distruttivo tubazioni (relining) | L27: Relining | M27: DA VERIFICARE | R27: 33 | S27: Registro chiamate 2026 – motivo 'RELINING' – tipologia 'Privato' – esito da inserire | T27: Zone senza striscioni/cartelloni
A28: 46057 | B28: Internet | C28: Nostro Sito | D28: Uzunov Srl | E28: Impresa edile / Artigiano | F28: 3318035418 | G28: uzunovsrl@gmail.com | H28: Finale Ligure | I28: SV | J28: RIFIUTI | K28: Smaltimento rifiuti pericolosi e non pericolosi | L28: Rifiuti | M28: DA VERIFICARE | R28: 4 | S28: Registro chiamate 2026 – motivo 'RIFIUTI' – tipologia 'Imp. Edile' – esito da inserire | T28: Zone senza striscioni/cartelloni
A29: 46061 | B29: Italiaonline | D29: Colaprico Alessandro | E29: Privato | F29: 3290183973 | G29: alessandro.colaprico@gmail.com | H29: Savona | I29: SV | J29: IGIENE IMPIANTI | K29: Pulizia canne fumarie (spazzacamino) | L29: Ispezione TV canne fumarie | M29: DA VERIFICARE | R29: 4 | S29: Registro chiamate 2026 – motivo 'IT CANNE' – tipologia 'Privato' – esito da inserire | T29: Zone senza striscioni/cartelloni
A30: 46062 | B30: Italiaonline | D30: Giommi Francesco | E30: Attività / Turismo | F30: 3534401472 | G30: renzanueva@gmail.com | H30: Finale Ligure | I30: SV | J30: DA SPECIFICARE | L30: Pulizia (specificare: cisterne, facciate, cappe…) | M30: DA VERIFICARE | R30: 34 | S30: Registro chiamate 2026 – motivo 'PULIZIA' – tipologia 'Attività' – esito da inserire | T30: Zone senza striscioni/cartelloni
A31: 46064 | B31: Italiaonline | D31: Mazzola Roberto | E31: Attività / Turismo | F31: 3204731050 | G31: info@mazzolamobili.it | H31: Dolceacqua | I31: IM | J31: BONIFICHE | K31: Rimozione e smaltimento amianto – eternit | L31: Amianto | M31: DA VERIFICARE | R31: 11 | S31: Registro chiamate 2026 – motivo 'AMIANTO' – tipologia 'Attività' – esito da inserire | T31: Zone senza striscioni/cartelloni
A32: 46070 | B32: Italiaonline | C32: Nostro Sito | D32: Giusto Giulia | E32: Privato | F32: 3474351879 | G32: giustogiulia@gmail.com | H32: Quiliano | I32: SV | J32: IGIENE IMPIANTI | K32: Pulizia canne fumarie (spazzacamino) | L32: Ispezione TV canne fumarie | M32: DA VERIFICARE | R32: 1 | S32: Registro chiamate 2026 – motivo 'IT CANNE' – tipologia 'Privato' – esito da inserire | T32: Zone senza striscioni/cartelloni
A33: 46070 | B33: Bus | C33: Nostro Sito | D33: Uzunov Adrian | E33: Impresa edile / Artigiano | F33: 3318035418 | G33: uzunovsrl@gmail.com | H33: Finale Ligure | I33: SV | J33: RIFIUTI | K33: Smaltimento rifiuti pericolosi e non pericolosi | L33: Rifiuti | M33: DA VERIFICARE | R33: 4 | S33: Registro chiamate 2026 – motivo 'RIFIUTI' – tipologia 'Imp. Edile' – esito da inserire | T33: Zone senza striscioni/cartelloni
A34: 46079 | B34: Italiaonline | C34: Nostro Sito | D34: Mai Stefano | E34: Privato | F34: 3333041279 | G34: stefanomai@gmail.com | H34: Zuccarello | I34: SV | J34: DISINFESTAZIONE | K34: Derattizzazione, disinfestazione insetti, disinfezione, sanificazione | L34: Derattizzazione | M34: DA VERIFICARE | R34: 34 | S34: Registro chiamate 2026 – motivo 'DERATIZZAZ' – tipologia 'Privato' – esito da inserire | T34: Zone senza striscioni/cartelloni
A35: 46080 | B35: Italiaonline | D35: Volpe Andrea | E35: Privato | F35: 3336347160 | G35: andrea.volpe@phd.unipi.it | H35: Boissano | I35: SV | J35: SPURGHI E RETI | K35: Rinnovamento non distruttivo tubazioni (relining) | L35: Relining | M35: DA VERIFICARE | R35: 33 | S35: Registro chiamate 2026 – motivo 'RELINING' – tipologia 'Privato' – esito da inserire | T35: Zone senza striscioni/cartelloni
A36: 46085 | B36: Internet | C36: Nostro Sito | D36: Nial Nizzoli Srl | E36: Impresa edile / Artigiano | F36: 3358021311 | G36: alberto.covri@nialnizzoli.com | H36: Calice Ligure | I36: SV | J36: RIFIUTI | K36: Smaltimento rifiuti pericolosi e non pericolosi | L36: Rifiuti | M36: DA VERIFICARE | R36: 4 | S36: Registro chiamate 2026 – motivo 'RIFIUTI' – tipologia 'Imp. Edile' – esito da inserire | T36: Zone senza striscioni/cartelloni
A37: 46093 | B37: Internet | C37: Nostro Sito | D37: Hpc Italia S.R.L. | E37: Azienda / Società | F37: 3771849892 | G37: arianna.russo@hpc.ag | H37: Milano | I37: MI | J37: DA SPECIFICARE | L37: Pulizia (specificare: cisterne, facciate, cappe…) | M37: DA VERIFICARE | R37: 4 | S37: Registro chiamate 2026 – motivo 'PULIZ.' – tipologia 'Società di' – esito da inserire | T37: Zone senza striscioni/cartelloni
A38: 46097 | B38: Internet | C38: Nostro Sito | D38: Edilservizi Srl | E38: Impresa edile / Artigiano | F38: 3288356330 | G38: paola.sirello@edilservizisrl.it | H38: Albissola | I38: SV | J38: BONIFICHE | K38: Rimozione e smaltimento amianto – eternit | L38: Amianto | M38: DA VERIFICARE | R38: 4 | S38: Registro chiamate 2026 – motivo 'AMIANTO' – tipologia 'Imp. Edile' – esito da inserire | T38: Zone senza striscioni/cartelloni
A39: 46097 | B39: Passaparola | D39: Turri Alice | E39: Attività / Turismo | F39: 3497721380 | H39: Finale Ligure | I39: SV | J39: RIFIUTI | K39: Smaltimento rifiuti pericolosi e non pericolosi | L39: Rifiuti | M39: DA VERIFICARE | R39: 4 | S39: Registro chiamate 2026 – motivo 'RIFIUTI' – tipologia 'Attività' – esito da inserire | T39: Zone senza striscioni/cartelloni
A40: 46097 | B40: Passaparola | D40: Enzo | E40: Privato | F40: +1(916)293-6674 | H40: Albenga | I40: SV | J40: SPURGHI E RETI | K40: Canaljet – autospurgo fosse biologiche, fognature, pozzetti, degrassatori | L40: Fognatura / spurgo | M40: DA VERIFICARE | R40: 34 | S40: Registro chiamate 2026 – motivo 'FOGNA' – tipologia 'Privato' – esito da inserire | T40: Albenga
A41: 46097 | B41: Internet | C41: Google | D41: Basadonne Antonella | E41: Attività / Turismo | F41: 3407815448 | H41: Savona | I41: SV | J41: RIFIUTI | K41: Smaltimento rifiuti pericolosi e non pericolosi | L41: Rifiuti | M41: DA VERIFICARE | R41: 34 | S41: Registro chiamate 2026 – motivo 'RIFIUTI' – tipologia 'Attività' – esito da inserire | T41: Zone senza striscioni/cartelloni
...

Sheet Servizi e obblighi
A1: Servizi e obblighi di legge
A2: Sintesi operativa per servizio – verificare sempre il testo vigente e l'iscrizione Albo aziendale
A4: N. | B4: Area | C4: Servizio | D4: Clienti tipici | E4: Codici EER tipici | F4: Autorizzazioni / qualifiche azienda | G4: Documenti per il lavoro e per il cliente | H4: Sicurezza lavoratori | I4: Mezzi e trasporto | J4: Note / punti critici | K4: Verifica interna (n. iscrizione, scadenza, chi)
